Workbook

Sheet Plan Cost
B2: PLAN COST | G3 DT
B7: NUM D'OFERTA | I7: NUM INF
B8: CLIENT / UBICACIÓ OBRA | J8: BCN
B9: DESCRIPCIÓ TITÒL | E9: EG HAB UNIF RUBI
B10: TIPUS | E10: Exploratory characterization studies.
B11: CENTRE COST | E11: Cataluña
B13: Persona Contacte | J13: RESUM
B14: Telèfon de Contacte | J14: NET VALUE | M14: =+(E36+E47+F65+E52)-(E36+E47+F65+E52)*G19 -> 669.1
B15: Mobil de Contacte | J15: TOTAL COST | M15: =+E36+E47+E52+E65*61.4 -> 667.9
B16: e-mail de Contacte | J16: MARGIN | M16: =+(M21-M15)/M21 -> 0.20488095
J17: HOURS | M17: =+E65 -> 5
B18: Assignació kilometratge (EUR / km) | G18: 0.19 | J18: SAP CTRL | M18: =IFERROR(IF(F65/E65>=40,(F65)/40,E65),0) -> 7.705
B19: Descompte comercial (%) | G19: 0 | J19: SUBCONTRACTING | M19: =+E36+E52 -> 360.9
J20: TRAVEL EXPENSES | M20: =+E47 -> 0
B21: Tecnic responsable | E21: Eva Vázquez Marcet | J21: OFFER AMOUNT | M21: =OFERTA!H70 -> 840
B23: Subcontracting | I23: Comments
B24: sondejos | E24: =OFERTA!H24 -> 325.9
B25: Calicates | E25: =OFERTA!H55 -> 0
B26: laboratori | E26: =OFERTA!H49 -> 35
B27: laboratorio 2
B28: Tasas
B29: <<otros>>
B30: Tubería PVC
B31: Arquetes
B32: Retirada residuos
B33: <<otros>>
B34: <<otros>>
B35: <<otros>>
B36: IMPORT TOTAL € | E36: =SUM(E24:G35) -> 360.9
B38: Travel expenses | I38: Comments
B39: Combustible | E39: =OFERTA!H66 -> 0 | I39: Km (9 litros/100 Km) = l * 1,80 €
B40: Peatjes
B41: Tren/avió/lloguer cotxes
B42: Hotel | E42: =OFERTA!L66 -> 0
B43: Esmorzar/dinar/sopar | E43: =OFERTA!I66+OFERTA!J66+OFERTA!K66 -> 0
B44: Despeses varies
B45: <<otros>>
B46: <<otros>>
B47: IMPORT TOTAL € | E47: =SUM(E39:G46) -> 0
B49: Internal subcontracting | I49: Comments
...

Sheet OFERTA
A1: PRESSUPOSTOS GEOTÈCCNICS
A2: CONCEPTE | B2: UNITATS | C2: PREU UNIT | D2: TOTAL | G2: SUBCONTRATACION SONDEOS
A3: SONDEIGS | G3: TPS
A4: P.A. Transporte equipos y personal | C4: 400 | D4: =(B4*C4) -> 0 | G4: 375 | H4: =B4*G4 -> 0 | I4: DESPLAZAMIENTO
A5: Emplaçament entre punts | C5: 51 | D5: =+B5*C5 -> 0 | G5: 50 | H5: =G5*B5 -> 0 | I5: Emplaçament entre punts
A6: ml de perforació en sòls fins a 20 m | C6: 43.41 | D6: =+B6*C6 -> 0 | G6: 38.41 | H6: =G6*B6 -> 0 | I6: ml de sòls fins a 20 m
A7: ml en roca tova fins a 20 m | C7: 51 | D7: =+B7*C7 -> 0 | G7: 46.09 | H7: =G7*B7 -> 0 | I7: ml de roques toves fins a 20 m
A8: ml en graves fins a 20 m | C8: 78 | D8: =+B8*C8 -> 0 | G8: 69 | H8: =G8*B8 -> 0 | I8: ml graves fins a 20 m
A9: ml en roca dura fins a 20 m | C9: 78 | D9: =+B9*C9 -> 0 | G9: 69 | H9: =G9*B9 -> 0 | I9: ml roca dura fins a 20 m
A10: ml de sòls fins de 20 a 40m | C10: =C6*1.2 -> 52.092 | D10: =+B10*C10 -> 0 | G10: =G6*1.2 -> 46.092 | H10: =G10*B10 -> 0 | I10: ml de sòls fins de 20 a 40m
A11: ml de roques toves de 20 a 40 m | C11: =C7*1.2 -> 61.2 | D11: =+B11*C11 -> 0 | G11: =G7*1.2 -> 55.308 | H11: =G11*B11 -> 0 | I11: ml de roques toves de 20 a 40 m
A12: ml de piezòmetre | C12: 18 | D12: =+B12*C12 -> 0 | G12: 12 | H12: =G12*B12 -> 0 | I12: ml piezometre
A13: Assaig Lefranc de permeabilitat | C13: 140 | D13: =+B13*C13 -> 0 | G13: 120 | H13: =G13*B13 -> 0 | I13: LEFRANC
A14: Assaig SPT | C14: 23 | D14: =+B14*C14 -> 0 | G14: 20.25 | H14: =G14*B14 -> 0 | I14: Assaig SPT
A15: mostra inalterada | C15: 23 | D15: =+B15*C15 -> 0 | G15: 21.25 | H15: =G15*B15 -> 0 | I15: mi
A16: caixa portatestimonis | C16: 12 | D16: =+B16*C16 -> 0 | G16: 9 | H16: =G16*B16 -> 0 | I16: PRESIOMETRES
A17: PA d'aigua per a la perforació de nivells rocosos | C17: 200 | D17: =+B17*C17 -> 0 | G17: 300 | H17: =G17*B17 -> 0 | I17: PA d'aigua
B18: Subtotal (1) | D18: =SUM(D4:D17) -> 0 | G18: 100 | H18: =B20*G18 -> 100 | I18: Desplaçament màquina de penetració
A19: ASSAIGS DPSH | G19: 8.9 | H19: =(B21*7)*G19 -> 186.9 | I19: ml penetració dinàmica DPSH
A20: Desplaçament de màquina de penetració | B20: 1 | C20: 110 | D20: =(B20*C20) -> 110 | G20: 18 | H20: =G20*B22 -> 18 | I20: ml previs
A21: unitat de penetració dinàmica DPSH | B21: 3 | C21: 120 | D21: =(B21*C21) -> 360 | G21: 21 | H21: =B23*G21 -> 21 | I21: sot
A22: ml previ | B22: 1 | C22: 45 | D22: =(B22*C22) -> 45 | G22: 35 | I22: obertura de paviment
A23: spt | B23: 1 | C23: 23 | D23: =(B23*C23) -> 23 | G23: 100 | I23: Testimoni de ferm
B24: Subtotal (2) | D24: =SUM(D20:D23) -> 538 | H24: =SUM(H4:H23) -> 325.9
A25: ASSAIGS DE LABORATORI
A26: Obertura de mostra | B26: 1 | C26: 5.93 | D26: =+B26*C26 -> 5.93 | G26: SUBCONTRATACIÓN LABORATORI
A27: Analisi granulomètric per tamissat | C27: 26.08 | D27: =+B27*C27 -> 0 | G27: SOIL-ASSAIG
A28: assaig de Limits d'Atterberg | C28: 27.76 | D28: =+B28*C28 -> 0 | G28: 4.75 | H28: =G28*B26 -> 4.75 | I28: Obertura de mostra
A29: compressió simple | C29: 31.5 | D29: =+B29*C29 -> 0 | G29: 23.34 | H29: =G29*B27 -> 0 | I29: Analisi granulomètric per tamissat
A30: tall directe UU | C30: 58 | D30: =+B30*C30 -> 0 | G30: 25.9 | H30: =G30*B28 -> 0 | I30: assaig de Limits d'Atterberg
A31: tall directe CD | C31: 120.45 | D31: =+B31*C31 -> 0 | G31: 30 | H31: =G31*B29 -> 0 | I31: permeabilitat
A32: permeabilitat en cèl·lula de edòmetre | C32: 85 | D32: =+B32*C32 -> 0 | G32: 40 | H32: =G32*B30 -> 0 | I32: tall directe UU
A33: Densitat aparent | C33: 10.1 | D33: =+B33*C33 -> 0 | G33: 43.75 | H33: =G33*B31 -> 0 | I33: inflament lliure
A34: Humitat natural | C34: 8.1 | D34: =+B34*C34 -> 0 | G34: 46.46 | H34: =G34*B32 -> 0 | I34: Lambe
A35: contingut en sulfats | B35: 1 | C35: 35 | D35: =+B35*C35 -> 35 | G35: 9.05 | H35: =G35*B33 -> 0 | I35: Densitat aparent
A36: Agressiviitat de l'aigua | C36: 118 | D36: =+B36*C36 -> 0 | G36: 7.15 | H36: =G36*B34 -> 0 | I36: Humitat natural
A37: Agressivitat dels sòls | C37: 60.47 | D37: =+B37*C37 -> 0 | G37: 30.25 | H37: =G37*B35 -> 30.25 | I37: compressió simple en roca
B38: Subtotal (3) | D38: =SUM(D26:D37) -> 40.93 | G38: 118.12 | H38: =G38*B36 -> 0 | I38: Agressiviitat de l'aigua
A39: INFORMES | G39: 54.97 | H39: =G39*B37 -> 0 | I39: Agressivitat dels sòls
A40: Redacció i direcció de l'estudi geotècnic | C40: 450 | D40: =B40*C40 -> 0 | G40: 28.61 | H40: =G40*B79 -> 0 | I40: Continugt en matèria orgànica
...

Sheet FACTURA M
A1: PRESSUPOSTOS GEOTÈCCNICS
A2: CONCEPTE | B2: UNITATS | C2: PREU UNIT | D2: TOTAL | G2: SUBCONTRATACION SONDEOS
A3: SONDEIGS | G3: TPS
A4: P.A. Transporte equipos y personal | C4: 510 | D4: =(B4*C4) -> 0 | G4: 450 | H4: =G4*B4 -> 0 | I4: DESPLAZAMIENTO
A5: Emplaçament entre punts | C5: 51 | D5: =+B5*C5 -> 0 | G5: 42 | H5: =G5*B5 -> 0 | I5: Emplaçament entre punts
A6: ml de sòls fins a 20 m | C6: 41.14 | D6: =+B6*C6 -> 0 | G6: 60 | H6: =G6*B6 -> 0 | I6: ml de sòls fins a 20 m
A7: ml de roques toves fins a 20 m | C7: 51 | D7: =+B7*C7 -> 0 | G7: 68.9 | H7: =G7*B7 -> 0 | I7: ml de roques toves fins a 20 m
A8: ml graves fins a 20 m | C8: 72.11 | D8: =+B8*C8 -> 0 | G8: 40.93 | H8: =G8*B8 -> 0 | I8: ml graves fins a 20 m
A9: ml roca dura fins a 20 m | C9: 68 | D9: =+B9*C9 -> 0 | G9: 61.73 | H9: =G9*B9 -> 0 | I9: ml roca dura fins a 20 m
A10: ml de sòls fins de 20 a 40m | C10: =C6*1.2 -> 49.368 | D10: =+B10*C10 -> 0 | G10: 66.03 | H10: =G10*B10 -> 0 | I10: ml de sòls fins de 20 a 40m
A11: ml de roques toves de 20 a 40 m | C11: =C7*1.2 -> 61.2 | D11: =+B11*C11 -> 0 | G11: 45 | H11: =G11*B11 -> 0 | I11: ml de roques toves de 20 a 40 m
A12: ml graves de 20 a 40 m | C12: =C8*1.2 -> 86.532 | D12: =+B12*C12 -> 0 | G12: 7.08 | H12: =G12*B12 -> 0 | I12: ml graves de 20 a 40 m
A13: ml roca dura de 20 a 40 m | C13: =C9*1.2 -> 81.6 | D13: =+B13*C13 -> 0 | G13: 11.13 | H13: =G13*B13 -> 0 | I13: ml roca dura de 20 a 40 m
A14: Assaig SPT | C14: 22 | D14: =+B14*C14 -> 0 | G14: 2.98 | H14: =G14*B14 -> 0 | I14: Assaig SPT
A15: Mostra inalterada | C15: 23 | D15: =+B15*C15 -> 0 | G15: 1.81 | H15: =G15*B15 -> 0 | I15: Mostra inalterada
A16: Mostra parafinada | C16: 12 | D16: =+B16*C16 -> 0 | G16: 51 | H16: =G16*B16 -> 0 | I16: Mostra parafinada
A17: Caixa de sondeigs | C17: 11 | D17: =+B17*C17 -> 0 | G17: 13 | H17: =G17*B17 -> 0 | I17: Caixa de sondeigs
B18: Subtotal (1) | D18: =SUM(D4:D17) -> 0 | G18: 12 | H18: =G18*B20 -> 0 | I18: Desplaçament màquina de penetració
A19: ASSAIGS DPSH | G19: 60 | H19: =G19*B21 -> 0 | I19: unitat de penetració dinàmica DPSH
A20: Desplaçament màquina de penetració | C20: 250 | D20: =(B20*C20) -> 0 | G20: 22 | H20: =G20*B22 -> 0 | I20: ml previa a l'assaig SPT
A21: unitat de penetració dinàmica DPSH | C21: 10 | D21: =(B21*C21) -> 0 | H21: =G21*B23 -> 0 | I21: SPT
A22: ml previa a l'assaig SPT | C22: 28 | D22: =(B22*C22) -> 0 | G22: 8 | H22: =B55 -> 1 | I22: Calicata manual
A23: SPT | C23: 28 | D23: =(B23*C23) -> 0 | G23: 28.5 | H23: =B73 -> 0 | I23: Testimoni de ferm
B24: Subtotal (2) | D24: =SUM(D20:D23) -> 0 | H24: =SUM(H4:H23) -> 1
A25: ASSAIGS DE LABORATORI
A26: Obertura de mostra | C26: 5.93 | D26: =+B26*C26 -> 0 | G26: SUBCONTRATACIÓN LABORATORI
A27: Analisi granulomètric per tamissat | C27: 26.08 | D27: =+B27*C27 -> 0
A28: assaig de Limits d'Atterberg | C28: 27.76 | D28: =+B28*C28 -> 0 | G28: 7.2 | H28: =G28*B26 -> 0 | I28: Obertura de mostra
A29: Compressió simple | C29: 37.1 | D29: =+B29*C29 -> 0 | G29: 2.7 | H29: =G29*B27 -> 0 | I29: Analisi granulomètric per tamissat
A30: tall directe UU | C30: 51.97 | D30: =+B30*C30 -> 0 | H30: =G30*B28 -> 0 | I30: assaig de Limits d'Atterberg
A31: Tall directe CD | C31: 120.45 | D31: =+B31*C31 -> 0 | G31: 27 | H31: =G31*B29 -> 0 | I31: Compressió simple
A32: Consolidació unidimensional | C32: 163.18 | D32: =+B32*C32 -> 0 | G32: 18 | H32: =G32*B30 -> 0 | I32: tall directe UU
A33: Densitat aparent | C33: 10.1 | D33: =+B33*C33 -> 0 | G33: 31.5 | H33: =G33*B31 -> 0 | I33: Tall directe CD
A34: Humitat natural | C34: 8.1 | D34: =+B34*C34 -> 0 | G34: 40.5 | H34: =G34*B32 -> 0 | I34: Consolidació unidimensional
A35: Continugt en sulfats | C35: 35 | D35: =+B35*C35 -> 0 | H35: =G35*B33 -> 0 | I35: Densitat aparent
A36: Agressiviitat de l'aigua | C36: 118 | D36: =+B36*C36 -> 0 | H36: =G36*B34 -> 0 | I36: Humitat natural
A37: Agressivitat dels sòls | C37: 60.47 | D37: =+B37*C37 -> 0 | G37: 31.5 | H37: =G37*B35 -> 0 | I37: Continugt en sulfats
B38: Subtotal (3) | D38: =SUM(D26:D37) -> 0 | G38: 151.2 | H38: =G38*B36 -> 0 | I38: Agressiviitat de l'aigua
A39: INFORMES | G39: 81 | H39: =G39*B37 -> 0 | I39: Agressivitat dels sòls
A40: Informe geotècnic | B40: 1 | C40: 1500 | D40: =B40*C40 -> 1500 | G40: 55 | H40: =G40*B79 -> 0 | I40: Continugt en matèria orgànica
...

Sheet Material Cost (lab)
A1: material cost (lab) | B1: max. 40 Characters | C1: max. 80 Characters | D1: max. 40 Characters2 | E1: max. 80 Characters3
A2: T13-380-00-G100001 | B2: Apertura y descripción de muestra | C2: Apertura y descripción de muestra de suelo, roca y/o áridos | D2: Sample opening and description | E2: Opening and description of soil, rock and/or aggregate samples
A3: T13-380-00-G100002 | B3: Preparación muestras ensayos de suelos | C3: Preparación de muestras para ensayos de suelos UNE 103-100-95 | D3: Soil test sample preparation | E3: Sample preparation for soil tests UNE 103-100-95
A4: T13-380-00-G100003 | B4: Remoldeo de pastilla para ensayo | C4: Remoldeo pastilla ensayo edométrico o CD o colapso o hinchamiento libre | D4: Test tablet topping | E4: Edometric/CD/collapse/free swelling test tablet remoulding
A5: T13-380-00-G100004 | B5: Remoldeo de una probeta para ensayo | C5: Remoldeo probeta para rotura a CS o triaxial o permeabilidad de 1,5 pulgadas | D5: Swirling of a test specimen | E5: Remoulding of specimen for CS or triaxial breakage or 1.5 inch permeability
A6: T13-380-00-G100005 | B6: Tallado muestra recibida en bloque | C6: Tallado de muestra recibida en bloque parafinado | D6: Carving of a sample received as a block | E6: Carving of specimen received in paraffin block
A7: T13-380-00-G100006 | B7: Tallado de muestra de testigo de sondeo | C7: Tallado de muestra de testigo de sondeo | D7: Cutting of core samples | E7: Carving of core sample
A8: T13-380-00-G100007 | B8: Preparación fracciones-mezcla materiales | C8: Preparación fracciones-mezcla materiales granulares para ensayo de compactación | D8: Preparation of fractions-mixed materials | E8: Preparation of granular material mix-fractions for compaction test
A9: T13-380-00-G100008 | B9: Molido muestra salida de tamiz 0,080 UNE | C9: Molido de muestra con 60 g de salida de tamiz 0,080 UNE | D9: Grinding sample coming out 0.080UNEsieve | E9: Grinding of sample with 60 g output of 0.080 UNE sieve
A10: T13-380-00-G110001 | B10: Determinación humedad secado estufa | C10: Determinación de la humedad de un suelo mediante secado en estufa UNE 103-300-93 | D10: Moisture determination oven-drying | E10: Determination of the humidity of a soil by drying in an oven UNE 103-300-93
A11: T13-380-00-G110002 | B11: Determinación de la densidad de un suelo | C11: Determinación densidad suelo. Método de la balanza hidrostática UNE 103-301-94 | D11: Determination of the density of a soil | E11: Determination of soil density. Hydrostatic balance method UNE 103-301-94
A12: T13-380-00-G110003 | B12: Determinación Límites de Atterberg | C12: Determinación Límites de Atterberg UNE 103-103-94 y 103-104-93 | D12: Determination of Atterberg limits | E12: Determination of Atterberg Limits UNE 103-103-94 y 103-104-93
... A152: T13-720-00-G500004 | B152: Coeficiente de friabilidad de las arenas | C152: Coeficiente de friabilidad de las arenas. UNE 83-115-89. | D152: Coefficient of friability of the sands | E152: Coefficient of friability of sands. UNE 83-115-89.

Sheet Material Cost
A1: TS | B1: TS-Product | C1: sevice id | D1: Service | E1: Client/obt | F1: Text | G1: Description | H1: more detailed description | I1: SubCod | J1: Material CODES
A2: TS-1000 | B2: Environmental characterization studies | C2: S10 | D2: Accredited environmental inspections (ENAC) | E2: 380 | F2: Exploratory characterization studies. | G2: Exploratory characterization studies. | H2: Basic characterization studies of the potential contamination of the soil and associated groundwater. | I2: 10 | J2: S10-380-10 | L2: Exploratory characterization studies. | M2: S10-380-10
C3: S10 | E3: 380 | F3: Detailed characterization studies. | G3: Detailed characterization studies. | H3: Complete characterization studies of the potential contamination of the soil and associated groundwater, which delimits the extent of the contamination. | I3: 20 | J3: S10-380-20 | L3: Detailed characterization studies. | M3: S10-380-20
C4: S10 | E4: 725 | F4: Certification of the quality of the remaining soil. | G4: Certification of the quality of the remaining soil. | H4: Soil characterization studies during the excavation of a potentially contaminated plot. | I4: 10 | J4: S10-725-10 | L4: Certification of the quality of the remaining soil. | M4: S10-725-10
C5: S10 | E5: 551 | F5: Control and monitoring of groundwater quality. | G5: Control and monitoring of groundwater quality. | H5: Establishment of potential groundwater contamination | I5: 10 | J5: S10-551-10 | L5: Control and monitoring of groundwater quality. | M5: S10-551-10
C6: G60 | D6: Unaccredited environmental studies. | E6: 134 | F6: Environmental impact studies. | G6: Environmental impact studies. | H6: Carrying out environmental impact studies for the implementation of civil works or industrial sites. | I6: 10 | J6: G60-134-10 | L6: Environmental impact studies. | M6: G60-134-10
C7: G60 | E7: 134 | F7: Quantitative risk analysis. | G7: Quantitative risk analysis. | H7: Quantitative risk assessment studies to determine the maximum allowable concentrations of a given pollutant or establish cleanup targets levels for a site. | I7: ´00 | J7: G60-134-´00 | L7: Quantitative risk analysis. | M7: G60-134-´00
B8: Soil and groundwater remediation | C8: G60 | D8: Remediation work. | E8: 725 | F8: Soil remediation projects. | G8: Soil remediation projects. | H8: Drafting of soil and associated groundwater remediation projects that allow the cleanup objectives to be achieved at a specific site. | I8: 10 | J8: G60-725-10 | L8: Soil remediation projects. | M8: G60-725-10
C9: G60 | E9: 129 | F9: Remediation monitoring reports. | G9: Remediation monitoring reports. | H9: Drafting of technical reports to monitor the remediation process of a site. | I9: 10 | J9: G60-129-10 | L9: Remediation monitoring reports. | M9: G60-129-10
A10: TS-1202 | B10: Geotechnical characterization studies | C10: S51 | D10: Geotechnical studies. | E10: 733 | F10: Geotechnical studies. | G10: Geotechnical studies for building. | H10: Drafting of geotechnical reports associated with building works (bearing capacity of the spoil, settlements, geotechnical characterization, etc.). | I10: 09 | J10: S51-733-09 | L10: Geotechnical studies for building. | M10: S51-733-09
C11: S51 | E11: 733 | G11: Slope stability studies. | H11: Geotechnical studies to characterize the stability of slopes in civil works (roads) or buildings (excavation holes for basements). | I11: 10 | J11: S51-733-10 | L11: Slope stability studies. | M11: S51-733-10
C12: S51 | E12: 733 | G12: Geotechnical studies of linear works (roads, gas pipelines, etc.) | H12: Geotechnical studies for the construction of linear works (establishing the degree of excavability and stability of the terrain, description of geotechnical problems, etc.). | I12: 20 | J12: S51-733-20 | L12: Geotechnical studies of linear works (roads, gas pipelines, etc.) | M12: S51-733-20
C13: T13 | D13: Laboratory tests of soil, rocks, agrregates, water and others. | E13: 380 | F13: Laboratory tests of soil, rocks, agrregates, water and others. | G13: #1 Laboratory tests on soil samples. | H13: Performance of physicochemical characterization tests, resistance, deformability, etc. In soil mechanics. | I13: 00 | J13: T13-380-00 | K13: +Subitems | L13: #1 Laboratory tests on soil samples. | M13: T13-380-00
C14: T13 | E14: 733 | G14: #2 Laboratory tests on rock samples. | H14: Performance of physicochemical characterization tests, resistance, deformability, etc. In rock mechanics. | I14: 00 | J14: T13-733-00 | L14: #2 Laboratory tests on rock samples. | M14: T13-733-00
C15: T13 | E15: 529 | G15: #3 Laboratory tests on aggregates samples. | H15: Performance of physicochemical characterization tests, resistance, deformability, etc. In aggregares. | I15: 00 | J15: T13-529-00 | L15: #3 Laboratory tests on aggregates samples. | M15: T13-529-00
C16: T13 | E16: 551 | G16: #4 Laboratory tests on water samples. | H16: Chemical characterization tests in water. | I16: 00 | J16: T13-551-00 | L16: #4 Laboratory tests on water samples. | M16: T13-551-00
C17: T13 | E17: 720 | G17: #5 Others laboratory tests. | H17: Others laboratory test (new test). | I17: 00 | J17: T13-720-00 | L17: #5 Others laboratory tests. | M17: T13-720-00
B19: Subcod 00 y/o 10 (00 = at home; 10= at the customer's site).

Sheet Cost Center
A1: Activity | B1: PtCtr
A2: Laboratory & Geothechnics studies | B2: 15803173
A3: Contaminated soils | B3: 15804173
A4: Remediation | B4: 15805173
A5: Cataluña | B5: 15806173

Sheet Technicians
A1: Técnicos
A2: Eva Vázquez Marcet
A3: Ariadna Salla
A4: Leian Martin
